Workbook

Sheet FORM-PR-051
A1: #VALUE! | C1: SISTEMA DE GESTÃO DA QUALIDADE | Y1: RO-PR-051
C3: RDR - RELATÓRIO DIÁRIO DE RECEBIMENTO - OUTUBRO 2025 | Y3: Rev. 05
A5: DESCRIÇÃO DO PRODUTO | I5: CRITÉRIO DE ACEITAÇÃO | L5: METROLOGIA | M5: CHECKLIST | W5: STATUS | Z5: RESPONSÁVEL
A6: DATA DA INSPEÇÃO | B6: FORNECEDOR | C6: DESCRIÇÃO | D6: QUANTIDADE | E6: NOTA FISCAL | F6: PEDIDO DE COMPRA + ITEM | G6: CORRIDA / RASTREAB. | H6: CERTIFICADO / RELAT. DIMENSIONAL | I6: PLANO DE CONTROLE | J6: MATERIAL (COMPONENTES CRÍTICOS) | K6: ESPECIFICAÇÃO DA ENGENHARIA | L6: INSTRUMENTO DE MEDIÇÃO | M6: ANÁLISE DE CERTIFICADO | N6: VISUAL | O6: IDENTIFICAÇÃO E RASTREAB. | P6: DIMENSIONAL | Q6: DUREZA (SH A) | R6: ID.LIGAS | S6: DUREZA TRAT. TÉRM. | T6: RANHURA (MSS-SP 6) | U6: 18-21 FIOS POR 1cm | V6: RUGOSIDADE E ACABAMENTO | W6: PEÇAS APROVADAS | X6: PEÇAS REPROVADAS | Y6: Nº RPNC | Z6: INSPETOR
A7: 45931 | B7: MARS | C7: BN USI NP CPL 8 FN (FURO LISO) | D7: 01 | E7: 000005548 | F7: 113600-18 | G7: 232/25 | H7: 290913 | I7: PC-NP-001 | J7: FN 65-45-12 | K7: =VLOOKUP(J7,DADOS!$A$3:$B$105,2,FALSE) -> EE-GI-001-008 | L7: IM0023/SE-014 | M7: TRUE | N7: TRUE | O7: TRUE | P7: TRUE | Q7: FALSE | R7: FALSE | S7: FALSE | T7: FALSE | U7: FALSE | V7: TRUE | W7: - | X7: 01 | Y7: 2025-0977 | Z7: PAULO
A8: 45931 | B8: MARS | C8: BN USI RFR CORPO WAFER DN-500 FN S1 | D8: 04 | E8: 000005545 | F8: 113851-06 | G8: C541 e C542 | I8: PC-RFR-001 | J8: FN 65-45-12 | K8: =VLOOKUP(J8,DADOS!$A$3:$B$105,2,FALSE) -> EE-GI-001-008 | L8: IM0023/SE-014 | M8: TRUE | N8: TRUE | O8: TRUE | P8: TRUE | Q8: FALSE | R8: FALSE | S8: FALSE | T8: TRUE | U8: TRUE | V8: TRUE | W8: - | X8: 04 | Y8: 2025-0978 | Z8: PAULO
A9: 45931 | B9: MARS | C9: BN USI RFR CORPO WAFER DN-500 FN S1 | D9: 04 | E9: 000005545 | F9: 113851-07 | G9: C541 e C542 | I9: PC-RFR-001 | J9: FN 65-45-12 | K9: =VLOOKUP(J9,DADOS!$A$3:$B$105,2,FALSE) -> EE-GI-001-008 | L9: IM0023/SE-014 | M9: TRUE | N9: TRUE | O9: TRUE | P9: TRUE | Q9: FALSE | R9: FALSE | S9: FALSE | T9: TRUE | U9: TRUE | V9: TRUE | W9: - | X9: 04 | Y9: 2025-0978 | Z9: PAULO
A10: 45931 | B10: MARS | C10: BN USI RFR CORPO WAFER DN-500 FN S1 | D10: 01 | E10: 000005545 | F10: 113851-08 | G10: C542 | I10: PC-RFR-001 | J10: FN 65-45-12 | K10: =VLOOKUP(J10,DADOS!$A$3:$B$105,2,FALSE) -> EE-GI-001-008 | L10: IM0023/SE-014 | M10: TRUE | N10: TRUE | O10: TRUE | P10: TRUE | Q10: FALSE | R10: FALSE | S10: FALSE | T10: TRUE | U10: TRUE | V10: TRUE | W10: - | X10: 01 | Y10: 2025-0978 | Z10: PAULO
A11: 45931 | B11: MARS | C11: BN USI NP CPL 6 FN (FURO LISO) | D11: 01 | E11: 000005543 | F11: 113600-15 | G11: 231/25 | H11: 290910 | I11: PC-NP-001 | J11: FN 65-45-12 | K11: =VLOOKUP(J11,DADOS!$A$3:$B$105,2,FALSE) -> EE-GI-001-008 | L11: IM0023/SE-014 | M11: TRUE | N11: TRUE | O11: TRUE | P11: TRUE | Q11: FALSE | R11: FALSE | S11: FALSE | T11: FALSE | U11: FALSE | V11: TRUE | W11: 01 | X11: - | Y11: - | Z11: PAULO
A12: 45931 | B12: MARS | C12: BN USI NP CPL 6 FN (FURO LISO) | D12: 16 | E12: 000005543 | F12: 113600-16 | G12: 231/25 | H12: 290910 | I12: PC-NP-001 | J12: FN 65-45-12 | K12: =VLOOKUP(J12,DADOS!$A$3:$B$105,2,FALSE) -> EE-GI-001-008 | L12: IM0023/SE-014 | M12: TRUE | N12: TRUE | O12: TRUE | P12: TRUE | Q12: FALSE | R12: FALSE | S12: FALSE | T12: FALSE | U12: FALSE | V12: TRUE | W12: 19 | X12: - | Y12: - | Z12: PAULO
A13: 45931 | B13: MARS | C13: BN USI NP CPL 6 FN (FURO LISO) | D13: 19 | E13: 000005543 | F13: 113600-17 | G13: 231/25 | H13: 290910 | I13: PC-NP-001 | J13: FN 65-45-12 | K13: =VLOOKUP(J13,DADOS!$A$3:$B$105,2,FALSE) -> EE-GI-001-008 | L13: IM0023/SE-014 | M13: TRUE | N13: TRUE | O13: TRUE | P13: TRUE | Q13: FALSE | R13: FALSE | S13: FALSE | T13: FALSE | U13: FALSE | V13: TRUE | W13: 16 | X13: - | Y13: - | Z13: PAULO
A14: 45931 | B14: MARS | C14: BC USI RL2 CPW 4" 150PSI CF8 | D14: 09 | E14: 000005550 | F14: 112066-01 | G14: 02072501 e 250425A1 | H14: 290909 | I14: PC-RL2-001 | J14: CF8 | K14: =VLOOKUP(J14,DADOS!$A$3:$B$105,2,FALSE) -> EE-GI-001-003 | L14: SE-014 | M14: TRUE | N14: TRUE | O14: TRUE | P14: TRUE | Q14: FALSE | R14: TRUE | S14: FALSE | T14: TRUE | U14: TRUE | V14: TRUE | W14: 09 | X14: - | Y14: - | Z14: PAULO
A15: 45931 | B15: MARS | C15: BC USI RL2 CPW 4" 150PSI CF8 | D15: 12 | E15: 000005550 | F15: 113732-01 | G15: 02072501, 250425A1 e 10022501 | H15: 290909 | I15: PC-RL2-001 | J15: CF8 | K15: =VLOOKUP(J15,DADOS!$A$3:$B$105,2,FALSE) -> EE-GI-001-003 | L15: SE-014 | M15: TRUE | N15: TRUE | O15: TRUE | P15: TRUE | Q15: FALSE | R15: TRUE | S15: FALSE | T15: TRUE | U15: TRUE | V15: TRUE | W15: 12 | X15: - | Y15: - | Z15: PAULO
A16: 45931 | B16: ILHA GRANDE | C16: WD DISCO 10 IN PN10 | D16: 04 | E16: 000025332 | F16: 114146-01 | G16: 07082501 | H16: 14734 | I16: PC-WD-001 | J16: CF8M | K16: =VLOOKUP(J16,DADOS!$A$3:$B$105,2,FALSE) -> EE-GI-001-002 | L16: SE-014 | M16: TRUE | N16: TRUE | O16: TRUE | P16: TRUE | Q16: FALSE | R16: TRUE | S16: FALSE | T16: FALSE | U16: FALSE | V16: FALSE | W16: 04 | X16: - | Y16: - | Z16: PAULO
A17: 45931 | B17: ILHA GRANDE | C17: NE DC 12" CF8M BRT | D17: 07 | E17: 000025334 | F17: 114497-04 | G17: 07082501 | H17: 14736 | I17: PC-NE-001 | J17: CF8M | K17: =VLOOKUP(J17,DADOS!$A$3:$B$105,2,FALSE) -> EE-GI-001-002 | L17: IM0023/SE-014 | M17: TRUE | N17: TRUE | O17: TRUE | P17: TRUE | Q17: FALSE | R17: TRUE | S17: FALSE | T17: FALSE | U17: FALSE | V17: FALSE | W17: 07 | X17: - | Y17: - | Z17: PAULO
A18: 45931 | B18: ILHA GRANDE | C18: NE DC 12" CF8M BRT | D18: 01 | E18: 000025335 | F18: 114661-01 | G18: 07082501 | H18: 14744 | I18: PC-NE-001 | J18: CF8M | K18: =VLOOKUP(J18,DADOS!$A$3:$B$105,2,FALSE) -> EE-GI-001-002 | L18: IM0023/SE-014 | M18: TRUE | N18: TRUE | O18: TRUE | P18: TRUE | Q18: FALSE | R18: TRUE | S18: FALSE | T18: FALSE | U18: FALSE | V18: FALSE | W18: 01 | X18: - | Y18: - | Z18: PAULO
A19: 45931 | B19: ILHA GRANDE | C19: NE DC 10" BRT CF8M | D19: 21 | E19: 000025331 | F19: 113888-01 | G19: 12082501 | H19: 14733 | I19: PC-NE-001 | J19: CF8M | K19: =VLOOKUP(J19,DADOS!$A$3:$B$105,2,FALSE) -> EE-GI-001-002 | L19: SE-014 | M19: TRUE | N19: TRUE | O19: TRUE | P19: TRUE | Q19: FALSE | R19: TRUE | S19: FALSE | T19: FALSE | U19: FALSE | V19: FALSE | W19: 21 | X19: - | Y19: - | Z19: PAULO
A20: 45931 | B20: ILHA GRANDE | C20: NE DC 10" BRT CF8M | D20: 04 | E20: 000025331 | F20: 113888-02 | G20: 12082501 | H20: 14733 | I20: PC-NE-001 | J20: CF8M | K20: =VLOOKUP(J20,DADOS!$A$3:$B$105,2,FALSE) -> EE-GI-001-002 | L20: SE-014 | M20: TRUE | N20: TRUE | O20: TRUE | P20: TRUE | Q20: FALSE | R20: TRUE | S20: FALSE | T20: FALSE | U20: FALSE | V20: FALSE | W20: 04 | X20: - | Y20: - | Z20: PAULO
A21: 45931 | B21: ILHA GRANDE | C21: NE DC 8" BRT CF8M | D21: 71 | E21: 000025331 | F21: 113888-03 | G21: 12082501 | H21: 14731 | I21: PC-NE-001 | J21: CF8M | K21: =VLOOKUP(J21,DADOS!$A$3:$B$105,2,FALSE) -> EE-GI-001-002 | L21: SE-014 | M21: TRUE | N21: TRUE | O21: TRUE | P21: TRUE | Q21: FALSE | R21: TRUE | S21: FALSE | T21: FALSE | U21: FALSE | V21: FALSE | W21: 71 | X21: - | Y21: - | Z21: PAULO
A22: 45931 | B22: ILHA GRANDE | C22: NE DISCO BRT 8" 250PSI CF8M | D22: 01 | E22: 000025341 | F22: 114601-01 | G22: 22072501 | H22: 14737 | I22: PC-NE-001 | J22: CF8M | K22: =VLOOKUP(J22,DADOS!$A$3:$B$105,2,FALSE) -> EE-GI-001-002 | L22: SE-014 | M22: TRUE | N22: TRUE | O22: TRUE | P22: TRUE | Q22: FALSE | R22: TRUE | S22: FALSE | T22: FALSE | U22: FALSE | V22: FALSE | W22: 01 | X22: - | Y22: - | Z22: PAULO
... A34: 45932 | B34: FUNDIÇÃO MUNDIAL | C34: RK DISCO BRT 30" 150# WCB | D34: 01 | E34: 000018104 | F34: 114208-02 | G34: 5355 | H34: 1323/2025 | I34: PC-RK-001 | J34: WCB | K34: =VLOOKUP(J34,DADOS!$A$3:$B$105,2,FALSE) -> EE-GI-001-001 | L34: IM0035/SE-014 | M34: TRUE | N34: TRUE | O34: TRUE | P34: TRUE | Q34: FALSE | R34: FALSE | S34: FALSE | T34: FALSE | U34: FALSE | V34: FALSE | W34: 01 | X34: - | Y34: - | Z34: PAULO
A35: 45932 | B35: R A DISTRIBUIDORA | C35: WD CPW BRT 22" PN10 FN | D35: 02 | E35: 000000605 | F35: 112934-03 | G35: C636 | I35: PC-WD-001 | J35: FN 65-45-12 | K35: =VLOOKUP(J35,DADOS!$A$3:$B$105,2,FALSE) -> EE-GI-001-008 | L35: IM0023/SE-014 | M35: TRUE | N35: TRUE | O35: TRUE | P35: TRUE | Q35: FALSE | R35: FALSE | S35: FALSE | T35: FALSE | U35: FALSE | V35: FALSE | W35: 02 | X35: - | Y35: - | Z35: PAULO
A36: 45932 | B36: R A DISTRIBUIDORA | C36: WD CPW BRT 22" PN10 FN | D36: 04 | E36: 000000605 | F36: 112934-04 | G36: C636 | I36: PC-WD-001 | J36: FN 65-45-12 | K36: =VLOOKUP(J36,DADOS!$A$3:$B$105,2,FALSE) -> EE-GI-001-008 | L36: IM0023/SE-014 | M36: TRUE | N36: TRUE | O36: TRUE | P36: TRUE | Q36: FALSE | R36: FALSE | S36: FALSE | T36: FALSE | U36: FALSE | V36: FALSE | W36: 04 | X36: - | Y36: - | Z36: PAULO
A37: 45932 | B37: ALISSON | C37: BN USI NP HS 10 IN 410 | D37: 08 | E37: 000000707 | F37: 113907-05 | G37: CA572 | H37: 707 | I37: PC-NP-001 | J37: 410 Condição A | K37: =VLOOKUP(J37,DADOS!$A$3:$B$105,2,FALSE) -> EE-GI-001-007 | L37: SE-014 | M37: TRUE | N37: TRUE | O37: TRUE | P37: TRUE | Q37: FALSE | R37: TRUE | S37: FALSE | T37: FALSE | U37: FALSE | V37: TRUE | W37: 08 | X37: - | Y37: - | Z37: PAULO
A38: 45932 | B38: ALISSON | C38: BN USI NE HS ESP SUP 5-6 410 2D PADRÃO KEYSTONE | D38: 10 | E38: 000000707 | F38: 114656-02 | G38: CA599 | H38: 707 | I38: PC-NE-001 | J38: 410 Condição A | K38: =VLOOKUP(J38,DADOS!$A$3:$B$105,2,FALSE) -> EE-GI-001-007 | L38: SE-014 | M38: TRUE | N38: TRUE | O38: TRUE | P38: TRUE | Q38: FALSE | R38: TRUE | S38: FALSE | T38: FALSE | U38: FALSE | V38: TRUE | W38: 10 | X38: - | Y38: - | Z38: PAULO
A39: 45933 | B39: HEITEC USINAGEM | C39: BN USI NE CPW 6" FN | D39: 10 | E39: 000000417 | F39: 112222-04 | G39: 128/25 | H39: 197/25 | I39: PC-NE-001 | J39: FN 65-45-12 | K39: =VLOOKUP(J39,DADOS!$A$3:$B$105,2,FALSE) -> EE-GI-001-008 | L39: IM-0319 | M39: TRUE | N39: TRUE | O39: TRUE | P39: TRUE | Q39: FALSE | R39: FALSE | S39: FALSE | T39: FALSE | U39: FALSE | V39: FALSE | W39: 10 | X39: - | Y39: - | Z39: CLEBER
A40: 45933 | B40: EXTRABOR | C40: BN VUL NE SEDE 3" GA1 | D40: 01 | E40: 000004361 | F40: 114797-01 | G40: 11173 | H40: 2127/25 | I40: PC-NE-001 | J40: NBR GA1 (Buna-N GA1) | K40: =VLOOKUP(J40,DADOS!$A$3:$B$105,2,FALSE) -> EE-GI-221-036 | L40: IM-0059 | M40: TRUE | N40: TRUE | O40: TRUE | P40: TRUE | Q40: TRUE | R40: FALSE | S40: FALSE | T40: FALSE | U40: FALSE | V40: FALSE | W40: 01 | X40: - | Y40: - | Z40: CLEBER
A41: 45933 | B41: R A DISTRIBUIDORA | C41: RT CPW 30" WCB BRT | D41: 04 | E41: 000000586 | F41: 114639-01 | G41: C616 | H41: 7339/25 | I41: PC-RT-001 | J41: WCB | K41: =VLOOKUP(J41,DADOS!$A$3:$B$105,2,FALSE) -> EE-GI-001-001 | L41: IM0035/SE-014 | M41: TRUE | N41: TRUE | O41: TRUE | P41: TRUE | Q41: FALSE | R41: FALSE | S41: FALSE | T41: FALSE | U41: FALSE | V41: FALSE | W41: 04 | X41: - | Y41: - | Z41: PAULO
A42: 45933 | B42: CASTING | C42: NE CPW BRT 8" FN | D42: 02 | E42: 000012540 | F42: 114691-02 | G42: 268/25 | H42: 5133/25 | I42: PC-NE-001 | J42: FN 65-45-12 | K42: =VLOOKUP(J42,DADOS!$A$3:$B$105,2,FALSE) -> EE-GI-001-008 | L42: IM0023/SE-014 | M42: TRUE | N42: TRUE | O42: TRUE | P42: TRUE | Q42: FALSE | R42: FALSE | S42: FALSE | T42: FALSE | U42: FALSE | V42: FALSE | W42: 02 | X42: - | Y42: - | Z42: PAULO
A43: 45933 | B43: CASTING | C43: NE CPW BRT 8" FN | D43: 05 | E43: 000012540 | F43: 114691-05 | G43: 268/25 | H43: 5133/25 | I43: PC-NE-001 | J43: FN 65-45-12 | K43: =VLOOKUP(J43,DADOS!$A$3:$B$105,2,FALSE) -> EE-GI-001-008 | L43: IM0023/SE-014 | M43: TRUE | N43: TRUE | O43: TRUE | P43: TRUE | Q43: FALSE | R43: FALSE | S43: FALSE | T43: FALSE | U43: FALSE | V43: FALSE | W43: 05 | X43: - | Y43: - | Z43: PAULO
A44: 45933 | B44: CASTING | C44: NE CPW BRT 8" FN | D44: 05 | E44: 000012540 | F44: 111833-06 | G44: 268/25 | H44: 5133/25 | I44: PC-NE-001 | J44: FN 65-45-12 | K44: =VLOOKUP(J44,DADOS!$A$3:$B$105,2,FALSE) -> EE-GI-001-008 | L44: IM0023/SE-014 | M44: TRUE | N44: TRUE | O44: TRUE | P44: TRUE | Q44: FALSE | R44: FALSE | S44: FALSE | T44: FALSE | U44: FALSE | V44: FALSE | W44: 05 | X44: - | Y44: - | Z44: PAULO
A45: 45933 | B45: CASTING | C45: NE CPW BRT 10" FN | D45: 06 | E45: 000012540 | F45: 111834-06 | G45: 272/25 | H45: 5135/25 | I45: PC-NE-001 | J45: FN 65-45-12 | K45: =VLOOKUP(J45,DADOS!$A$3:$B$105,2,FALSE) -> EE-GI-001-008 | L45: IM0023/SE-014 | M45: TRUE | N45: TRUE | O45: TRUE | P45: TRUE | Q45: FALSE | R45: FALSE | S45: FALSE | T45: FALSE | U45: FALSE | V45: FALSE | W45: 06 | X45: - | Y45: - | Z45: PAULO
A46: 45933 | B46: CLEVER | C46: BN VUL NE SEDE 8" ELASTOHARD | D46: 05 | E46: 000012425 | F46: 113872-02 | G46: 000107337 | H46: 293/25 | I46: PC-NE-001 | J46: ELASTOHARD | K46: =VLOOKUP(J46,DADOS!$A$3:$B$105,2,FALSE) -> EE-GI-221-064 | L46: IM-0059 | M46: TRUE | N46: TRUE | O46: TRUE | P46: TRUE | Q46: TRUE | R46: FALSE | S46: FALSE | T46: FALSE | U46: FALSE | V46: FALSE | W46: 05 | X46: - | Y46: - | Z46: CLEBER
A47: 45933 | B47: CLEVER | C47: BN VUL NE SEDE 8" ELASTOHARD | D47: 05 | E47: 000012425 | F47: 113903-03 | G47: 000107337 | H47: 293/25 | I47: PC-NE-001 | J47: ELASTOHARD | K47: =VLOOKUP(J47,DADOS!$A$3:$B$105,2,FALSE) -> EE-GI-221-064 | L47: IM-0059 | M47: TRUE | N47: TRUE | O47: TRUE | P47: TRUE | Q47: TRUE | R47: FALSE | S47: FALSE | T47: FALSE | U47: FALSE | V47: FALSE | W47: 03 | X47: - | Y47: - | Z47: CLEBER
A48: 45933 | B48: CLEVER | C48: BN VUL NE SEDE 8" ELASTOHARD | D48: 08 | E48: 000012425 | F48: 111543-06 | G48: 000107337 | H48: 293/25 | I48: PC-NE-001 | J48: ELASTOHARD | K48: =VLOOKUP(J48,DADOS!$A$3:$B$105,2,FALSE) -> EE-GI-221-064 | L48: IM-0059 | M48: TRUE | N48: TRUE | O48: TRUE | P48: TRUE | Q48: TRUE | R48: FALSE | S48: FALSE | T48: FALSE | U48: FALSE | V48: FALSE | W48: 08 | X48: - | Y48: - | Z48: CLEBER
... A125: 45937 | B125: MS USINAGEM | C125: BN USI NE CPW 12" FN | D125: 12 | E125: 000006329 | F125: 114513-05 | G125: 239/25 | H125: N/A | I125: PC-NE-001 | J125: FN 65-45-12 | K125: =VLOOKUP(J125,DADOS!$A$3:$B$105,2,FALSE) -> EE-GI-001-008 | L125: IM-0319 | M125: FALSE | N125: TRUE | O125: TRUE | P125: TRUE | Q125: FALSE | R125: FALSE | S125: FALSE | T125: FALSE | U125: FALSE | V125: FALSE | W125: 12 | X125: - | Y125: - | Z125: CLEBER
A126: 45937 | B126: MARS | C126: BC USI RL2 CPW 4" 150 PSI CF8 | D126: 04 | E126: 000005555 | F126: 113732-01 | G126: 02072501 e 250425A1 | I126: PC-RL2-001 | J126: CF8 | K126: =VLOOKUP(J126,DADOS!$A$3:$B$105,2,FALSE) -> EE-GI-001-003 | L126: IM-0319 | M126: TRUE | N126: TRUE | O126: TRUE | P126: TRUE | Q126: FALSE | R126: TRUE | S126: FALSE | T126: FALSE | U126: FALSE | V126: FALSE | W126: 04 | X126: - | Y126: - | Z126: CLEBER
A127: 45937 | B127: CALMOTECH | C127: BR USI WR3 ANEL RET SD 20" SAE 1020 | D127: 01 | E127: 00000605 | F127: 113548-34 | G127: CFA122 | H127: 230/2025 | I127: PC-WR-001 | J127: CHAPA SAE 1020 | K127: =VLOOKUP(J127,DADOS!$A$3:$B$105,2,FALSE) -> EE-GI-001-072 | L127: IM-0023 | M127: TRUE | N127: TRUE | O127: TRUE | P127: TRUE | Q127: FALSE | R127: TRUE | S127: FALSE | T127: FALSE | U127: FALSE | V127: TRUE | W127: 01 | X127: - | Y127: - | Z127: CLEBER
A128: 45937 | B128: CALMOTECH | C128: BR USI WR3 ANEL RET SD 20" SAE 1020 | D128: 01 | E128: 00000605 | F128: 113548-33 | G128: CFA122 | H128: 230/2025 | I128: PC-WR-001 | J128: CHAPA SAE 1020 | K128: =VLOOKUP(J128,DADOS!$A$3:$B$105,2,FALSE) -> EE-GI-001-072 | L128: IM-0023 | M128: TRUE | N128: TRUE | O128: TRUE | P128: TRUE | Q128: FALSE | R128: TRUE | S128: FALSE | T128: FALSE | U128: FALSE | V128: TRUE | W128: 01 | X128: - | Y128: - | Z128: CLEBER
A129: 45937 | B129: CALMOTECH | C129: BR USI WR3 ANEL RET SD 20" SAE 1020 | D129: 01 | E129: 00000605 | F129: 113548-32 | G129: CFA122 | H129: 230/2025 | I129: PC-WR-001 | J129: CHAPA SAE 1020 | K129: =VLOOKUP(J129,DADOS!$A$3:$B$105,2,FALSE) -> EE-GI-001-072 | L129: IM-0023 | M129: TRUE | N129: TRUE | O129: TRUE | P129: TRUE | Q129: FALSE | R129: TRUE | S129: FALSE | T129: FALSE | U129: FALSE | V129: TRUE | W129: 01 | X129: - | Y129: - | Z129: CLEBER
...

Sheet DADOS
A1: ESPECIFICAÇÕES | D1: PLANOS DE CONTROLE
A2: - | B2: - | D2: -
A3: 17-4PH | B3: EE-GI-001-011 | D3: PC-DS-001
A4: 17-4PH - NACE | B4: EE-GI-001-064 | D4: PC-MR-001
A5: 1B CD4MCuN | B5: EE-GI-001-020 | D5: PC-MS7-001
A6: 304 Condição A | B6: EE-GI-001-023 | D6: PC-MSCOPASA-001
A7: 316 Condição A | B7: EE-GI-001-006 | D7: PC-NE-001
A8: 316 Condição B | B8: EE-GI-001-010 | D8: PC-NF-001
A9: 316 Condição S | B9: EE-GI-001-021 | D9: PC-NP-001
A10: 316/316L NACE | B10: EE-GI-001-065 | D10: PC-NT-001
A11: 316L Condição B | B11: EE-GI-001-052 | D11: PC-NW-001
A12: 410 Condição A | B12: EE-GI-001-007 | D12: PC-RFR-001
A13: 410 Condição T | B13: EE-GI-001-024 | D13: PC-RK-001
... A21: 6A CD3WCuN | B21: EE-GI-001-037 | D21: PC-WR-001
A22: Borracha Natural | B22: EE-GI-221-045
A23: Buna-N Branca | B23: EE-GI-221-040
A24: Buna-N CPF Série MS | B24: EE-GI-024-014
A25: C955 | B25: EE-GI-001-015
A26: C95800 | B26: EE-GI-001-031
A27: C95800 (SWS) | B27: EE-GI-021-008
A28: CA15 | B28: EE-GI-001-004
A29: CF3 | B29: EE-GI-001-013
A30: CF3M | B30: EE-GI-001-012
A31: CF3M (SWS) | B31: EE-GI-021-018
A32: CF8 | B32: EE-GI-001-003
A33: CF8M | B33: EE-GI-001-002
... A105: WCB (SWS) | B105: EE-GI-021-009
